Workbook

Sheet Summary
A1: Interview Questions — Combined Workbook
A3: Batch 1 — Company SQL (305)
A4: Total | B4: =COUNTA(Index_305!B2:B306) -> 305
A5: Easy | B5: =COUNTIF(Index_305!E:E,"Easy") -> 111
A6: Medium | B6: =COUNTIF(Index_305!E:E,"Medium") -> 167
A7: Hard | B7: =COUNTIF(Index_305!E:E,"Hard") -> 27
A9: Batch 2 — Mixed-tech (167)
A10: Total | B10: =COUNTA(Index_167!B2:B168) -> 167
A11: Linux | B11: =COUNTIF(Index_167!C:C,"Linux") -> 2
A12: Docker | B12: =COUNTIF(Index_167!C:C,"Docker") -> 1
A13: SQL | B13: =COUNTIF(Index_167!C:C,"SQL") -> 28
A14: Snowflake | B14: =COUNTIF(Index_167!C:C,"Snowflake") -> 22
A15: Spark | B15: =COUNTIF(Index_167!C:C,"Spark") -> 20
A16: Programming | B16: =COUNTIF(Index_167!C:C,"Programming") -> 79
A17: Git | B17: =COUNTIF(Index_167!C:C,"Git") -> 15
A19: Batch 3 — Company Git (12)
A20: Total | B20: =COUNTA(Index_Git12!B2:B13) -> 12
A21: Easy | B21: =COUNTIF(Index_Git12!D:D,"Easy") -> 7
A22: Medium | B22: =COUNTIF(Index_Git12!D:D,"Medium") -> 5
A23: Free | B23: =COUNTIF(Index_Git12!#REF!,"Free") -> #REF!
A24: Premium | B24: =COUNTIF(Index_Git12!#REF!,"Premium") -> #REF!
A26: Batch 4 — Company Snowflake (51)
A27: Total | B27: =COUNTA(Index_SF51!B2:B52) -> 51
A28: Easy | B28: =COUNTIF(Index_SF51!E:E,"Easy") -> 20
A29: Medium | B29: =COUNTIF(Index_SF51!E:E,"Medium") -> 16
A30: Hard | B30: =COUNTIF(Index_SF51!E:E,"Hard") -> 15
A32: Batch 5 — Company Programming/Python (175)
A33: Total | B33: =COUNTA(Index_PY175!B2:B176) -> 175
A34: Easy | B34: =COUNTIF(Index_PY175!E:E,"Easy") -> 48
A35: Medium | B35: =COUNTIF(Index_PY175!E:E,"Medium") -> 102
A36: Hard | B36: =COUNTIF(Index_PY175!E:E,"Hard") -> 25
A37: Free | B37: =COUNTIF(Index_PY175!#REF!,"Free") -> #REF!
A38: Premium | B38: =COUNTIF(Index_PY175!#REF!,"Premium") -> #REF!
A40: Grand total questions | B40: =B4+B10+B20+B27+B33 -> 710

Sheet Index_305
A1: # | B1: Question | C1: Company | D1: Type | E1: Difficulty
A2: 1 | B2: Average Order Value | C2: Accenture | D2: SQL / Aggregation | E2: Easy
A3: 2 | B3: Find Cheapest Product | C3: Apple | D3: SQL / Aggregation | E3: Easy
A4: 3 | B4: New vs. Returning Customer Report | C4: RedHat | D4: SQL / Joins | E4: Easy
A5: 4 | B5: Self-Join for Manager Names | C5: Backblaze | D5: SQL / Joins | E5: Easy
A6: 5 | B6: Join Employees and Departments | C6: Adobe | D6: SQL / Joins | E6: Easy
A7: 6 | B7: Find Highest Salary | C7: JaneStreet | D7: SQL / Aggregation | E7: Easy
A8: 7 | B8: Filter Orders by Date Range | C8: Google | D8: SQL / Basic | E8: Easy
A9: 8 | B9: Join Three Tables | C9: AMD | D9: SQL / Joins | E9: Easy
A10: 9 | B10: Pivot Daily Sales | C10: Google | D10: SQL / Aggregation | E10: Easy
A11: 10 | B11: Find Customers Without Orders | C11: LinkedIn | D11: SQL / Joins | E11: Easy
A12: 11 | B12: Use COALESCE for Null Handling | C12: Samsung | D12: SQL / Data Manipulation | E12: Easy
A13: 12 | B13: Self-Join for Hierarchical Data | C13: Broadcom | D13: SQL / Advanced | E13: Easy
... A306: 305 | B306: Complex Data Warehouse Aggregation and Trend Analysis for Multi-Channel Sales Optimization | C306: SAP | D306: SQL / Aggregation | E306: Hard

Sheet Solutions_305
A1: # | B1: Question | C1: Difficulty | D1: Inferred Schema | E1: SQL Solution
A2: 1 | B2: Average Order Value | C2: Easy | D2: orders(order_id, customer_id, order_total, order_date) | E2: SELECT AVG(order_total) AS avg_order_value FROM orders;
A3: 2 | B3: Find Cheapest Product | C3: Easy | D3: products(product_id, name, price) | E3: SELECT product_id, name, price FROM products ORDER BY price ASC LIMIT 1;
A4: 3 | B4: New vs. Returning Customer Report | C4: Easy | D4: orders(order_id, customer_id, order_date) | E4: SELECT CASE WHEN COUNT(*) = 1 THEN 'New' ELSE 'Returning' END AS customer_type, COUNT(DISTINCT customer_id) AS customers FROM (SELECT customer_id, COUNT(*) AS cnt FROM orders GROUP BY customer_id) t GROUP BY CASE WHEN cnt = 1 THEN 'New' ELSE 'Returning' END;
A5: 4 | B5: Self-Join for Manager Names | C5: Easy | D5: employees(emp_id, name, manager_id) | E5: SELECT e.name AS employee, m.name AS manager FROM employees e LEFT JOIN employees m ON e.manager_id = m.emp_id;
A6: 5 | B6: Join Employees and Departments | C6: Easy | D6: employees(emp_id, name, dept_id), departments(dept_id, dept_name) | E6: SELECT e.name, d.dept_name FROM employees e JOIN departments d ON e.dept_id = d.dept_id;
A7: 6 | B7: Find Highest Salary | C7: Easy | D7: employees(emp_id, name, salary) | E7: SELECT MAX(salary) AS highest_salary FROM employees;
A8: 7 | B8: Filter Orders by Date Range | C8: Easy | D8: orders(order_id, order_date, amount) | E8: SELECT * FROM orders WHERE order_date BETWEEN DATE '2025-01-01' AND DATE '2025-03-31';
A9: 8 | B9: Join Three Tables | C9: Easy | D9: orders(o), customers(c), products(p) via order_items(order_id, product_id) | E9: SELECT o.order_id, c.name AS customer, p.name AS product FROM orders o JOIN customers c ON o.customer_id = c.customer_id JOIN order_items oi ON o.order_id = oi.order_id JOIN products p ON oi.product_id = p.product_id;
A10: 9 | B10: Pivot Daily Sales | C10: Easy | D10: sales(sale_date, amount) | E10: SELECT sale_date, SUM(CASE WHEN amount > 0 THEN amount END) AS positive_sales, COUNT(*) AS txn_count FROM sales GROUP BY sale_date ORDER BY sale_date;
A11: 10 | B11: Find Customers Without Orders | C11: Easy | D11: customers(customer_id, name), orders(order_id, customer_id) | E11: SELECT c.customer_id, c.name FROM customers c LEFT JOIN orders o ON c.customer_id = o.customer_id WHERE o.order_id IS NULL;
A12: 11 | B12: Use COALESCE for Null Handling | C12: Easy | D12: employees(emp_id, name, bonus) | E12: SELECT emp_id, name, COALESCE(bonus, 0) AS bonus FROM employees;
A13: 12 | B13: Self-Join for Hierarchical Data | C13: Easy | D13: employees(emp_id, name, manager_id) | E13: WITH RECURSIVE hierarchy AS ( SELECT emp_id, name, manager_id, 1 AS level FROM employees WHERE manager_id IS NULL UNION ALL SELECT e.emp_id, e.name, e.manager_id, h.level+1 FROM employees e JOIN hierarchy h ON e.manager_id = h.emp_id) SELECT * FROM hierarchy ORDER BY level, emp_id;
... A306: 305 | B306: Complex Data Warehouse Aggregation and Trend Analysis for Multi-Channel Sales Optimization | C306: Hard | D306: sales(channel, sale_date, amount) | E306: WITH monthly AS ( SELECT channel, DATE_TRUNC('month', sale_date) AS mo, SUM(amount) AS total FROM sales GROUP BY channel, DATE_TRUNC('month', sale_date)) SELECT channel, mo, total, AVG(total) OVER (PARTITION BY channel ORDER BY mo ROWS BETWEEN 2 PRECEDING AND CURRENT ROW) AS rolling_3mo, 100.0*(total-LAG(total) OVER (PARTITION BY channel ORDER BY mo))/NULLIF(LAG(total) OVER (PARTITION BY channel ORDER BY mo),0) AS mom_pct FROM monthly;

Sheet Index_167
A1: # | B1: Question | C1: Tech | D1: Subtopic
A2: 1 | B2: Debug SSH Lockout | C2: Linux
A3: 2 | B3: Recursive Keyword Finder | C3: Linux
A4: 3 | B4: Docker Multi-Architecture Image | C4: Docker
A5: 4 | B5: Average Order Value | C5: SQL | D5: Aggregation
A6: 5 | B6: Join Employees and Departments | C6: SQL | D6: Joins
A7: 6 | B7: Filter Orders by Date Range | C7: SQL | D7: Basic
A8: 7 | B8: Find Customers Without Orders | C8: SQL | D8: Joins
A9: 8 | B9: Use COALESCE for Null Handling | C9: SQL | D9: Data Manipulation
A10: 9 | B10: Merge Multiple Address Fields | C10: SQL | D10: Data Manipulation
A11: 10 | B11: String Concatenation in SELECT | C11: SQL | D11: Data Manipulation
A12: 11 | B12: Find Nth Highest Revenue | C12: SQL | D12: Aggregation
A13: 12 | B13: Self-Join to Identify Missing Supervisors | C13: SQL | D13: Joins
A14: 13 | B14: Year-over-Year Revenue Growth | C14: SQL | D14: Aggregation
A15: 14 | B15: Above Average Price Products | C15: SQL | D15: Advanced
A16: 15 | B16: Calculate Cumulative Sales | C16: SQL | D16: Aggregation
... A112: 111 | B112: Partition Labels | C112: Programming | D112: Strings
A113: 112 | B113: Create Branch from Detached HEAD State | C113: Git
A114: 113 | B114: Rebase Feature Branch | C114: Git
A115: 114 | B115: Apply Specific Stash from Multiple Stashes | C115: Git
A116: 115 | B116: Remove Last Commit and Discard Changes | C116: Git
A117: 116 | B117: Checkout Single File from Another Branch | C117: Git
A118: 117 | B118: Cherry-Pick Specific Commit | C118: Git
A119: 118 | B119: Restore File to Previous Version | C119: Git
A120: 119 | B120: Create an Annotated Tag | C120: Git
A121: 120 | B121: Add Git Submodule | C121: Git
A122: 121 | B122: Update Submodule to Latest Commit | C122: Git
A123: 122 | B123: Stash Work, Fix Bug, Restore and Update | C123: Git
A124: 123 | B124: Remove File from Entire Git History | C124: Git
... A127: 126 | B127: Recover Lost Commits from Detached HEAD | C127: Git
A128: 127 | B128: Merge Customer Records from Two Sources | C128: Snowflake | D128: Combining Data
A129: 128 | B129: Filter Funded Startups | C129: Snowflake | D129: Aggregation
A130: 129 | B130: Assign Row Numbers to Authors per Paper | C130: Snowflake | D130: Windows Functions
A131: 130 | B131: Amusement Park Rating Anomalies | C131: Snowflake | D131: Aggregate Functions
A132: 131 | B132: Usage and Accuracy per Model Type | C132: Snowflake | D132: Aggregation
A133: 132 | B133: Find the Last Climber per Mountain | C133: Snowflake | D133: Windows Functions
A134: 133 | B134: Track Product Purchases | C134: Snowflake | D134: Windows Functions
A135: 134 | B135: Most Common Order Status | C135: Spark | D135: DataFrame
A136: 135 | B136: Calculating Overtime Pay | C136: Spark | D136: Joins
A137: 136 | B137: Top Products by Revenue | C137: Spark | D137: DataFrame
...

Sheet Solutions_167
A1: # | B1: Question | C1: Tech | D1: Subtopic | E1: Solution
A2: 1 | B2: Debug SSH Lockout | C2: Linux | E2: # From console / recovery shell: sudo systemctl status sshd sudo journalctl -u sshd -n 100 --no-pager sudo sshd -t # validate config sudo grep -E 'PermitRoot|PasswordAuth|AllowUsers' /etc/ssh/sshd_config sudo tail -50 /var/log/auth.log # or /var/log/secure on RHEL # Common fixes: sudo ufw allow 22/tcp # firewall sudo chmod 700 ~/.ssh && chmod 600 ~/.ssh/authorized_keys sudo systemctl restart sshd
A3: 2 | B3: Recursive Keyword Finder | C3: Linux | E3: # grep recursively, ignoring binaries, with line numbers: grep -rniI --color=auto --include='*.py' 'TODO' . # faster alternative: rg -n 'TODO' . # ripgrep # with file list only: grep -rl 'keyword' /path
A4: 3 | B4: Docker Multi-Architecture Image | C4: Docker | E4: # Build & push for amd64 + arm64 with buildx: docker buildx create --name mb --use docker buildx inspect --bootstrap docker buildx build \ --platform linux/amd64,linux/arm64 \ -t myrepo/app:1.0 \ --push . docker buildx imagetools inspect myrepo/app:1.0
A5: 4 | B5: Average Order Value | C5: SQL | D5: Aggregation | E5: SELECT AVG(order_total) AS avg_order_value FROM orders;
A6: 5 | B6: Join Employees and Departments | C6: SQL | D6: Joins | E6: SELECT e.name, d.dept_name FROM employees e JOIN departments d ON e.dept_id = d.dept_id;
A7: 6 | B7: Filter Orders by Date Range | C7: SQL | D7: Basic | E7: SELECT * FROM orders WHERE order_date BETWEEN DATE '2025-01-01' AND DATE '2025-03-31';
A8: 7 | B8: Find Customers Without Orders | C8: SQL | D8: Joins | E8: SELECT c.customer_id, c.name FROM customers c LEFT JOIN orders o ON c.customer_id = o.customer_id WHERE o.order_id IS NULL;
A9: 8 | B9: Use COALESCE for Null Handling | C9: SQL | D9: Data Manipulation | E9: SELECT emp_id, name, COALESCE(bonus, 0) AS bonus FROM employees;
A10: 9 | B10: Merge Multiple Address Fields | C10: SQL | D10: Data Manipulation | E10: SELECT customer_id, CONCAT_WS(', ', street, city, state, zip) AS full_address FROM customers;
A11: 10 | B11: String Concatenation in SELECT | C11: SQL | D11: Data Manipulation | E11: SELECT first_name || ' ' || last_name AS full_name FROM employees;
A12: 11 | B12: Find Nth Highest Revenue | C12: SQL | D12: Aggregation | E12: -- Nth highest (here N=3): SELECT DISTINCT revenue FROM orders ORDER BY revenue DESC OFFSET 2 LIMIT 1;
A13: 12 | B13: Self-Join to Identify Missing Supervisors | C13: SQL | D13: Joins | E13: SELECT e.emp_id, e.name FROM employees e LEFT JOIN employees s ON e.supervisor_id = s.emp_id WHERE e.supervisor_id IS NOT NULL AND s.emp_id IS NULL;
A14: 13 | B14: Year-over-Year Revenue Growth | C14: SQL | D14: Aggregation | E14: SELECT year, revenue, 100.0*(revenue - LAG(revenue) OVER (ORDER BY year))/NULLIF(LAG(revenue) OVER (ORDER BY year),0) AS yoy_pct FROM annual_revenue;
A15: 14 | B15: Above Average Price Products | C15: SQL | D15: Advanced | E15: SELECT * FROM products WHERE price > (SELECT AVG(price) FROM products);
A16: 15 | B16: Calculate Cumulative Sales | C16: SQL | D16: Aggregation | E16: SELECT sale_date, amount, SUM(amount) OVER (ORDER BY sale_date) AS cumulative FROM sales;
... A112: 111 | B112: Partition Labels | C112: Programming | D112: Strings | E112: def partitionLabels(s): last = {c: i for i, c in enumerate(s)} res, start, end = [], 0, 0 for i, c in enumerate(s): end = max(end, last[c]) if i == end: res.append(end - start + 1); start = i+1 return res
A113: 112 | B113: Create Branch from Detached HEAD State | C113: Git | E113: git checkout -b new-branch-name # or: git switch -c new-branch-name
A114: 113 | B114: Rebase Feature Branch | C114: Git | E114: git checkout feature git fetch origin git rebase origin/main # resolve conflicts, then: git add . && git rebase --continue git push --force-with-lease
A115: 114 | B115: Apply Specific Stash from Multiple Stashes | C115: Git | E115: git stash list # find the index, e.g. stash@{2} git stash apply stash@{2} # keep it in stash list # git stash pop stash@{2} # apply and drop
A116: 115 | B116: Remove Last Commit and Discard Changes | C116: Git | E116: git reset --hard HEAD~1
A117: 116 | B117: Checkout Single File from Another Branch | C117: Git | E117: git checkout other-branch -- path/to/file.py # or: git restore --source=other-branch path/to/file.py
A118: 117 | B118: Cherry-Pick Specific Commit | C118: Git | E118: git cherry-pick <commit-sha> # add -x to record source commit
A119: 118 | B119: Restore File to Previous Version | C119: Git | E119: git log -- path/to/file.py # find the commit git checkout <commit-sha> -- path/to/file.py # or: git restore --source=<sha> path/to/file.py
A120: 119 | B120: Create an Annotated Tag | C120: Git | E120: git tag -a v1.0.0 -m "Release 1.0.0" git push origin v1.0.0
A121: 120 | B121: Add Git Submodule | C121: Git | E121: git submodule add https://github.com/org/lib.git external/lib git commit -m "Add lib submodule" # Cloning later: git clone --recurse-submodules <repo>
A122: 121 | B122: Update Submodule to Latest Commit | C122: Git | E122: git submodule update --remote --merge external/lib git add external/lib && git commit -m "Bump lib submodule"
A123: 122 | B123: Stash Work, Fix Bug, Restore and Update | C123: Git | E123: git stash push -m "WIP feature" git checkout main && git pull # fix bug, commit, push git checkout feature git stash pop # restore work git rebase main # incorporate the fix
A124: 123 | B124: Remove File from Entire Git History | C124: Git | E124: # Preferred (fast, safe): git filter-repo --path secrets.env --invert-paths # Or with the older filter-branch: git filter-branch --force --index-filter \ 'git rm --cached --ignore-unmatch secrets.env' \ --prune-empty --tag-name-filter cat -- --all git push --force --all
... A127: 126 | B127: Recover Lost Commits from Detached HEAD | C127: Git | E127: git reflog # find the lost SHA git checkout -b recovered <sha> # or: git branch recovered <sha>
A128: 127 | B128: Merge Customer Records from Two Sources | C128: Snowflake | D128: Combining Data | E128: MERGE INTO customers t USING staging_customers s ON t.customer_id = s.customer_id WHEN MATCHED THEN UPDATE SET t.name=s.name, t.email=s.email, t.updated_at=CURRENT_TIMESTAMP() WHEN NOT MATCHED THEN INSERT (customer_id, name, email) VALUES (s.customer_id, s.name, s.email);
A129: 128 | B129: Filter Funded Startups | C129: Snowflake | D129: Aggregation | E129: SELECT company_id, name, SUM(amount) AS total_funding FROM funding_rounds GROUP BY company_id, name HAVING SUM(amount) >= 1000000;
A130: 129 | B130: Assign Row Numbers to Authors per Paper | C130: Snowflake | D130: Windows Functions | E130: SELECT paper_id, author_id, ROW_NUMBER() OVER (PARTITION BY paper_id ORDER BY author_order) AS author_seq FROM paper_authors;
A131: 130 | B131: Amusement Park Rating Anomalies | C131: Snowflake | D131: Aggregate Functions | E131: WITH stats AS ( SELECT ride_id, AVG(rating) AS mu, STDDEV(rating) AS sd FROM ratings GROUP BY ride_id) SELECT r.* FROM ratings r JOIN stats s USING (ride_id) WHERE ABS(r.rating - s.mu) > 2 * s.sd;
A132: 131 | B132: Usage and Accuracy per Model Type | C132: Snowflake | D132: Aggregation | E132: SELECT model_type, COUNT(*) AS calls, AVG(CASE WHEN predicted = actual THEN 1.0 ELSE 0 END) AS accuracy FROM model_predictions GROUP BY model_type;
A133: 132 | B133: Find the Last Climber per Mountain | C133: Snowflake | D133: Windows Functions | E133: SELECT mountain_id, climber_id, summit_ts FROM ( SELECT *, ROW_NUMBER() OVER (PARTITION BY mountain_id ORDER BY summit_ts DESC) rn FROM climbs ) WHERE rn = 1;
A134: 133 | B134: Track Product Purchases | C134: Snowflake | D134: Windows Functions | E134: SELECT customer_id, product_id, purchase_ts, ROW_NUMBER() OVER (PARTITION BY customer_id, product_id ORDER BY purchase_ts) AS purchase_no FROM purchases;
A135: 134 | B135: Most Common Order Status | C135: Spark | D135: DataFrame | E135: from pyspark.sql.functions import count mode = (orders.groupBy("status").agg(count("*").alias("n")) .orderBy("n", ascending=False).limit(1))
A136: 135 | B136: Calculating Overtime Pay | C136: Spark | D136: Joins | E136: from pyspark.sql.functions import col, when, greatest, lit pay = (timecards.join(employees, "emp_id") .withColumn("overtime_hours", greatest(col("hours_worked") - lit(40), lit(0))) .withColumn("overtime_pay", col("overtime_hours") * col("hourly_rate") * 1.5))
A137: 136 | B137: Top Products by Revenue | C137: Spark | D137: DataFrame | E137: from pyspark.sql.functions import sum as _sum top = (sales.groupBy("product_id").agg(_sum("amount").alias("rev")) .orderBy("rev", ascending=False).limit(10))
...

Sheet Index_Git12
A1: # | B1: Question | C1: Company | D1: Difficulty
A2: 1 | B2: Restore File to Previous Version | C2: Slack | D2: Medium
A3: 2 | B3: Create Branch from Detached HEAD State | C3: CGI | D3: Easy
A4: 3 | B4: View Unique Commits Branch vs Origin | C4: EPAM | D4: Easy
A5: 4 | B5: Create an Annotated Tag | C5: Nintendo | D5: Medium
A6: 5 | B6: Remove All Untracked Files and Folders | C6: EY | D6: Easy
A7: 6 | B7: Add Git Submodule | C7: EY | D7: Medium
A8: 7 | B8: Update Submodule to Latest Commit | C8: GoDaddy | D8: Medium
A9: 8 | B9: Convert Remote from HTTPS to SSH | C9: EPAM | D9: Easy
A10: 9 | B10: Rebase Feature Branch | C10: GitHub | D10: Easy
A11: 10 | B11: Stash Work, Fix Bug, Restore and Update | C11: IBM | D11: Medium
A12: 11 | B12: Apply Specific Stash from Multiple Stashes | C12: UBS | D12: Easy
A13: 12 | B13: Rename Branch and Update All References | C13: Zoom | D13: Easy

Sheet Solutions_Git12
A1: # | B1: Question | C1: Company | D1: Difficulty | E1: Solution
A2: 1 | B2: Restore File to Previous Version | C2: Slack | D2: Medium | E2: # Find the commit you want to restore from: git log -- path/to/file.py # Restore that file to the chosen commit's version (modern syntax): git restore --source=<commit-sha> -- path/to/file.py # Equivalent older syntax: git checkout <commit-sha> -- path/to/file.py # Verify, then commit the restore: git status git add path/to/file.py git commit -m "Restore file.py to version from <sha>"
A3: 2 | B3: Create Branch from Detached HEAD State | C3: CGI | D3: Easy | E3: # After checking out a tag/SHA you'll be in detached HEAD. # Verify state: git status # → "HEAD detached at <sha>" # Create a branch here so commits aren't lost: git switch -c new-branch-name # modern # or: git checkout -b new-branch-name # classic # Push it upstream: git push -u origin new-branch-name
A4: 3 | B4: View Unique Commits Branch vs Origin | C4: EPAM | D4: Easy | E4: # Always fetch first so origin refs are current: git fetch origin # Commits on local feature that origin/feature doesn't have: git log origin/feature..feature --oneline # Commits on origin/feature that local doesn't have: git log feature..origin/feature --oneline # Both directions side by side (left = local, right = remote): git log --left-right --graph --oneline feature...origin/feature # Just the count: git rev-list --left-right --count feature...origin/feature
A5: 4 | B5: Create an Annotated Tag | C5: Nintendo | D5: Medium | E5: # Annotated tag (recommended for releases — has author, date, message): git tag -a v1.0.0 -m "Release 1.0.0" # Tag a specific commit instead of HEAD: git tag -a v1.0.0 <commit-sha> -m "Release 1.0.0" # Verify: git tag -n git show v1.0.0 # Push the single tag: git push origin v1.0.0 # or push all tags: git push origin --tags
A6: 5 | B6: Remove All Untracked Files and Folders | C6: EY | D6: Easy | E6: # DRY RUN first — see what would be removed: git clean -nd # Include files ignored by .gitignore in the preview: git clean -ndx # Remove untracked files AND directories: git clean -fd # Remove everything untracked, including ignored files (DESTRUCTIVE): git clean -fdx # Interactive mode if you want to pick: git clean -i
A7: 6 | B7: Add Git Submodule | C7: EY | D7: Medium | E7: # Add a submodule into ./external/lib: git submodule add https://github.com/org/lib.git external/lib # This creates .gitmodules and stages both it and the submodule pointer. git status git commit -m "Add lib as submodule" git push # Anyone cloning later needs: git clone --recurse-submodules <repo-url> # Or, if already cloned: git submodule update --init --recursive
A8: 7 | B8: Update Submodule to Latest Commit | C8: GoDaddy | D8: Medium | E8: # Update one submodule to the latest commit on its tracked branch: git submodule update --remote --merge external/lib # Update all submodules: git submodule update --remote --merge # The parent repo now has a new submodule pointer — commit it: git add external/lib git commit -m "Bump lib submodule to latest" git push # Inspect what changed inside the submodule: git diff --submodule=log
A9: 8 | B9: Convert Remote from HTTPS to SSH | C9: EPAM | D9: Easy | E9: # See current remotes: git remote -v # origin https://github.com/org/repo.git (fetch) # origin https://github.com/org/repo.git (push) # Switch to SSH: git remote set-url origin git@github.com:org/repo.git # Verify: git remote -v # origin git@github.com:org/repo.git (fetch) # origin git@github.com:org/repo.git (push) # Test the SSH connection: ssh -T git@github.com git fetch
A10: 9 | B10: Rebase Feature Branch | C10: GitHub | D10: Easy | E10: # Make sure main is current: git fetch origin git checkout feature # Rebase feature onto the latest main: git rebase origin/main # If conflicts: # edit files, then: git add <resolved-files> git rebase --continue # (or `git rebase --abort` to back out) # Push the rewritten history safely: git push --force-with-lease
A11: 10 | B11: Stash Work, Fix Bug, Restore and Update | C11: IBM | D11: Medium | E11: # 1. Save in-progress work (include untracked): git stash push -u -m "WIP feature-x" # 2. Switch to main and fix the bug: git checkout main git pull # ... fix bug ... git add . git commit -m "Hotfix: critical bug" git push origin main # 3. Back to feature, restore stash, rebase onto fixed main: git checkout feature-x git stash pop # restores work, drops the stash entry git rebase main # incorporate the hotfix # resolve any conflicts → git add ... && git rebase --continue
A12: 11 | B12: Apply Specific Stash from Multiple Stashes | C12: UBS | D12: Easy | E12: # List stashes with their indexes: git stash list # stash@{0}: WIP on feature: ... # stash@{1}: WIP on bugfix: ... # stash@{2}: WIP on main: ... # Preview what's inside a specific stash: git stash show -p stash@{2} # Apply it (keeps it in the stash list): git stash apply stash@{2} # Or apply AND remove from the list: git stash pop stash@{2} # Drop a stash without applying it: git stash drop stash@{2}
A13: 12 | B13: Rename Branch and Update All References | C13: Zoom | D13: Easy | E13: # Rename the LOCAL branch (run while on it): git branch -m new-name # Or rename a different branch by name: git branch -m old-name new-name # Push the new branch and set upstream: git push -u origin new-name # Delete the old branch from the remote: git push origin --delete old-name # Tell collaborators to update their refs: git fetch origin --prune git branch -u origin/new-name new-name # if upstream tracking is missing

Sheet Index_SF51
A1: # | B1: Question | C1: Company | D1: Subtopic | E1: Difficulty
A2: 1 | B2: Filter Popular Videos on a Streaming Platform | C2: Apple | D2: Filtering | E2: Easy
A3: 2 | B3: Combine Customer Orders and Products | C3: Twilio | D3: Joins | E3: Medium
A4: 3 | B4: Summarize Rental Income per Landlord | C4: Broadcom | D4: Joins | E4: Hard
A5: 4 | B5: Anonymize User PII Data for a Social Media Platform | C5: Atlassian | D5: String Functions | E5: Medium
A6: 5 | B6: Calculate Average Price and Order Count by Category | C6: Shopify | D6: Joins | E6: Easy
A7: 6 | B7: Replace Keywords in Social Media Post Text | C7: PayPal | D7: String Replacement | E7: Easy
A8: 7 | B8: Rank Top Products by Revenue per Category | C8: Coinbase | D8: Window Functions | E8: Hard
A9: 8 | B9: Count Daily Customers and Total Call Duration | C9: Amazon | D9: Aggregation | E9: Easy
A10: 9 | B10: Assign Row Numbers to Authors per Paper | C10: Cloudflare | D10: Window Functions | E10: Medium
A11: 10 | B11: Product Sales and Inventory Data | C11: PayPal | D11: Aggregation | E11: Medium
A12: 11 | B12: Filter Movies with Missing Box Office Data | C12: DoorDash | D12: Null Handling | E12: Easy
A13: 12 | B13: Merge Customer Records from Two Sources | C13: Lyft | D13: Combining Data | E13: Easy
... A52: 51 | B52: Stars and Planets | C52: Cloudflare | D52: Joins | E52: Easy

Sheet Solutions_SF51
A1: # | B1: Question | C1: Company | D1: Difficulty | E1: Inferred Schema | F1: SQL Solution
A2: 1 | B2: Filter Popular Videos on a Streaming Platform | C2: Apple | D2: Easy | E2: videos(video_id, title, views, status, uploaded_at) | F2: SELECT video_id, title, views FROM videos WHERE status = 'published' AND views > 1000000 ORDER BY views DESC;
A3: 2 | B3: Combine Customer Orders and Products | C3: Twilio | D3: Medium | E3: customers(customer_id, name), orders(order_id, customer_id, order_ts), order_items(order_id, product_id, qty), products(product_id, name, price) | F3: SELECT c.name AS customer, o.order_id, p.name AS product, oi.qty, oi.qty * p.price AS line_total FROM customers c JOIN orders o ON c.customer_id = o.customer_id JOIN order_items oi ON o.order_id = oi.order_id JOIN products p ON oi.product_id = p.product_id ORDER BY o.order_id;
A4: 3 | B4: Summarize Rental Income per Landlord | C4: Broadcom | D4: Hard | E4: landlords(landlord_id, name), properties(property_id, landlord_id), leases(lease_id, property_id, start_date, end_date), payments(payment_id, lease_id, amount, paid_on) | F4: SELECT l.landlord_id, l.name, COUNT(DISTINCT p.property_id) AS properties, COUNT(DISTINCT le.lease_id) AS active_leases, COALESCE(SUM(pay.amount), 0) AS total_income, COALESCE(AVG(pay.amount), 0) AS avg_payment FROM landlords l LEFT JOIN properties p ON l.landlord_id = p.landlord_id LEFT JOIN leases le ON p.property_id = le.property_id LEFT JOIN payments pay ON le.lease_id = pay.lease_id GROUP BY l.landlord_id, l.name ORDER BY total_income DESC;
A5: 4 | B5: Anonymize User PII Data for a Social Media Platform | C5: Atlassian | D5: Medium | E5: users(user_id, email, phone, first_name, last_name, dob) | F5: SELECT user_id, SHA2(email, 256) AS email_hash, REGEXP_REPLACE(phone, '\\d(?=\\d{4})', '*') AS phone_masked, LEFT(first_name, 1) || REPEAT('*', LENGTH(first_name) - 1) AS first_masked, LEFT(last_name, 1) || REPEAT('*', LENGTH(last_name) - 1) AS last_masked, YEAR(dob) AS birth_year_only FROM users;
A6: 5 | B6: Calculate Average Price and Order Count by Category | C6: Shopify | D6: Easy | E6: products(product_id, category, price), order_items(order_id, product_id, qty) | F6: SELECT p.category, AVG(p.price) AS avg_price, COUNT(oi.order_id) AS order_count, SUM(oi.qty) AS units_sold FROM products p LEFT JOIN order_items oi ON p.product_id = oi.product_id GROUP BY p.category ORDER BY p.category;
A7: 6 | B7: Replace Keywords in Social Media Post Text | C7: PayPal | D7: Easy | E7: posts(post_id, content) | F7: SELECT post_id, REGEXP_REPLACE(content, '\\b(spam|abuse|hate|profanity)\\b', '***', 1, 0, 'i') AS cleaned_content FROM posts;
A8: 7 | B8: Rank Top Products by Revenue per Category | C8: Coinbase | D8: Hard | E8: sales(sale_id, product_id, amount), products(product_id, name, category) | F8: SELECT category, product_id, name, revenue, rk FROM ( SELECT p.category, p.product_id, p.name, SUM(s.amount) AS revenue, RANK() OVER (PARTITION BY p.category ORDER BY SUM(s.amount) DESC) AS rk FROM sales s JOIN products p ON s.product_id = p.product_id GROUP BY p.category, p.product_id, p.name ) WHERE rk <= 3 ORDER BY category, rk;
A9: 8 | B9: Count Daily Customers and Total Call Duration | C9: Amazon | D9: Easy | E9: calls(call_id, customer_id, call_ts, duration_sec) | F9: SELECT DATE(call_ts) AS day, COUNT(DISTINCT customer_id) AS unique_customers, SUM(duration_sec) AS total_duration_sec, SUM(duration_sec) / 60 AS total_duration_min FROM calls GROUP BY DATE(call_ts) ORDER BY day;
A10: 9 | B10: Assign Row Numbers to Authors per Paper | C10: Cloudflare | D10: Medium | E10: paper_authors(paper_id, author_id, contribution_score, author_order) | F10: SELECT paper_id, author_id, ROW_NUMBER() OVER (PARTITION BY paper_id ORDER BY author_order, author_id) AS author_seq FROM paper_authors ORDER BY paper_id, author_seq;
A11: 10 | B11: Product Sales and Inventory Data | C11: PayPal | D11: Medium | E11: products(product_id, name), sales(sale_id, product_id, qty, sold_at), inventory(product_id, on_hand, reorder_point) | F11: SELECT p.product_id, p.name, COALESCE(SUM(s.qty), 0) AS units_sold, MAX(i.on_hand) AS current_stock, MAX(i.reorder_point) AS reorder_point, CASE WHEN MAX(i.on_hand) <= MAX(i.reorder_point) THEN 'REORDER' ELSE 'OK' END AS stock_status FROM products p LEFT JOIN sales s ON p.product_id = s.product_id LEFT JOIN inventory i ON p.product_id = i.product_id GROUP BY p.product_id, p.name;
A12: 11 | B12: Filter Movies with Missing Box Office Data | C12: DoorDash | D12: Easy | E12: movies(movie_id, title, release_year, box_office) | F12: SELECT movie_id, title, release_year FROM movies WHERE box_office IS NULL OR box_office = 0 ORDER BY release_year DESC;
A13: 12 | B13: Merge Customer Records from Two Sources | C13: Lyft | D13: Easy | E13: customers(customer_id, name, email, updated_at), staging_customers(customer_id, name, email, updated_at) | F13: MERGE INTO customers t USING staging_customers s ON t.customer_id = s.customer_id WHEN MATCHED AND s.updated_at > t.updated_at THEN UPDATE SET t.name = s.name, t.email = s.email, t.updated_at = s.updated_at WHEN NOT MATCHED THEN INSERT (customer_id, name, email, updated_at) VALUES (s.customer_id, s.name, s.email, s.updated_at);
... A52: 51 | B52: Stars and Planets | C52: Cloudflare | D52: Easy | E52: stars(star_id, name, spectral_type), planets(planet_id, star_id, name, mass_earth, orbital_period_days) | F52: SELECT s.name AS star, s.spectral_type, COUNT(p.planet_id) AS planet_count, AVG(p.mass_earth) AS avg_planet_mass, MIN(p.orbital_period_days) AS shortest_orbit_days, MAX(p.orbital_period_days) AS longest_orbit_days FROM stars s LEFT JOIN planets p ON s.star_id = p.star_id GROUP BY s.name, s.spectral_type ORDER BY planet_count DESC;

Sheet Index_PY175
A1: # | B1: Question | C1: Company | D1: Subtopic | E1: Difficulty
A2: 1 | B2: Top K Frequent Elements in Stream | C2: JPMorgan | D2: Hash Tables | E2: Medium
A3: 2 | B3: Skew-Aware Key Partitioner | C3: Okta | D3: Hash Tables | E3: Medium
A4: 3 | B4: Moving Average from Data Stream | C4: Amazon | D4: Queues | E4: Easy
A5: 4 | B5: LFU Cache | C5: Amazon | D5: Hash Tables | E5: Hard
A6: 5 | B6: Find Median from Data Stream | C6: Okta | D6: Heaps | E6: Hard
A7: 6 | B7: Hash Join Simulator | C7: Apple | D7: Hash Tables | E7: Medium
A8: 7 | B8: Event Stream Deduplicator | C8: Google | D8: Hash Tables | E8: Medium
A9: 8 | B9: Log Aggregator | C9: Microsoft | D9: Hash Tables | E9: Medium
A10: 9 | B10: Min Stack | C10: Google | D10: Stacks | E10: Medium
A11: 10 | B11: Design Twitter | C11: Google | D11: Hash Table | E11: Medium
A12: 11 | B12: Design Add and Search Words Data Structure | C12: Google | D12: String | E12: Medium
A13: 12 | B13: Implement Trie (Prefix Tree) | C13: Google | D13: Hash Table | E13: Medium
... A176: 175 | B176: Minimum Interval to Include Each Query | C176: Qualcomm | D176: Arrays | E176: Hard

Sheet Solutions_PY175
A1: # | B1: Question | C1: Company | D1: Subtopic | E1: Difficulty | F1: Solution
A2: 1 | B2: Top K Frequent Elements in Stream | C2: JPMorgan | D2: Hash Tables | E2: Medium | F2: from collections import Counter import heapq class TopKStream: def __init__(self, k): self.k, self.cnt = k, Counter() def add(self, x): self.cnt[x] += 1 def top(self): return [v for v, _ in self.cnt.most_common(self.k)]
A3: 2 | B3: Skew-Aware Key Partitioner | C3: Okta | D3: Hash Tables | E3: Medium | F3: import hashlib class SkewAwarePartitioner: def __init__(self, n_partitions, hot_keys, salt_factor=8): self.n = n_partitions self.hot = set(hot_keys) self.salt = salt_factor def partition(self, key, row_index=0): # Salt hot keys to spread load across multiple partitions k = f"{key}#{row_index % self.salt}" if key in self.hot else key return int(hashlib.md5(k.encode()).hexdigest(), 16) % self.n
A4: 3 | B4: Moving Average from Data Stream | C4: Amazon | D4: Queues | E4: Easy | F4: from collections import deque class MovingAverage: def __init__(self, size): self.q = deque(maxlen=size) self.s = 0 def next(self, val): if len(self.q) == self.q.maxlen: self.s -= self.q[0] self.q.append(val) self.s += val return self.s / len(self.q)
A5: 4 | B5: LFU Cache | C5: Amazon | D5: Hash Tables | E5: Hard | F5: from collections import defaultdict, OrderedDict class LFUCache: def __init__(self, capacity): self.cap = capacity self.min_freq = 0 self.key_to_val = {} # key -> value self.key_to_freq = {} # key -> freq self.freq_to_keys = defaultdict(OrderedDict) # freq -> ordered keys def _bump(self, key): f = self.key_to_freq[key] del self.freq_to_keys[f][key] if not self.freq_to_keys[f]: del self.freq_to_keys[f] if self.min_freq == f: self.min_freq += 1 self.key_to_freq[key] = f + 1 self.freq_to_keys[f + 1][key] = None def get(self, key): if key not in self.key_to_val: return -1 self._bump(key) return self.key_to_val[key] def put(self, key, value): if self.cap <= 0: return if key in self.key_to_val: self.key_to_val[key] = value self._bump(key) return if len(self.key_to_val) >= self.cap: evict, _ = self.freq_to_keys[self.min_freq].popitem(last=False) del self.key_to_val[evict]; del self.key_to_freq[evict] self.key_to_val[key] = value self.key_to_freq[key] = 1 self.freq_to_keys[1][key] = None self.min_freq = 1
A6: 5 | B6: Find Median from Data Stream | C6: Okta | D6: Heaps | E6: Hard | F6: import heapq class MedianFinder: def __init__(self): self.lo = [] # max-heap (negated) self.hi = [] # min-heap def addNum(self, num): heapq.heappush(self.lo, -num) heapq.heappush(self.hi, -heapq.heappop(self.lo)) if len(self.hi) > len(self.lo): heapq.heappush(self.lo, -heapq.heappop(self.hi)) def findMedian(self): if len(self.lo) > len(self.hi): return -self.lo[0] return (-self.lo[0] + self.hi[0]) / 2
A7: 6 | B7: Hash Join Simulator | C7: Apple | D7: Hash Tables | E7: Medium | F7: from collections import defaultdict def hash_join(left, right, lkey, rkey): idx = defaultdict(list) for r in right: idx[r[rkey]].append(r) out = [] for l in left: for r in idx.get(l[lkey], []): out.append({**l, **r}) return out
A8: 7 | B8: Event Stream Deduplicator | C8: Google | D8: Hash Tables | E8: Medium | F8: from collections import deque class Deduplicator: def __init__(self, ttl_seconds): self.ttl = ttl_seconds self.seen = {} self.q = deque() def is_new(self, event_id, ts): # evict expired while self.q and self.q[0][1] + self.ttl < ts: eid, _ = self.q.popleft() self.seen.pop(eid, None) if event_id in self.seen: return False self.seen[event_id] = ts self.q.append((event_id, ts)) return True
A9: 8 | B9: Log Aggregator | C9: Microsoft | D9: Hash Tables | E9: Medium | F9: from collections import defaultdict class LogAggregator: def __init__(self, bucket_seconds=60): self.buckets = defaultdict(int) self.bs = bucket_seconds def add(self, ts, key, val=1): self.buckets[(ts // self.bs, key)] += val def query(self, bucket_id, key): return self.buckets.get((bucket_id, key), 0) def top(self, bucket_id, k=10): items = [(key, v) for (b, key), v in self.buckets.items() if b == bucket_id] return sorted(items, key=lambda x: -x[1])[:k]
A10: 9 | B10: Min Stack | C10: Google | D10: Stacks | E10: Medium | F10: class MinStack: def __init__(self): self.s, self.m = [], [] def push(self, x): self.s.append(x) self.m.append(x if not self.m else min(x, self.m[-1])) def pop(self): self.s.pop(); self.m.pop() def top(self): return self.s[-1] def getMin(self): return self.m[-1]
A11: 10 | B11: Design Twitter | C11: Google | D11: Hash Table | E11: Medium | F11: import heapq from collections import defaultdict class Twitter: def __init__(self): self.t = 0 self.tweets = defaultdict(list) # user -> [(time, tweetId)] self.follows = defaultdict(set) def postTweet(self, u, tid): self.t += 1 self.tweets[u].append((self.t, tid)) def getNewsFeed(self, u): h = [] for v in self.follows[u] | {u}: for ts, tid in self.tweets[v][-10:]: heapq.heappush(h, (-ts, tid)) return [heapq.heappop(h)[1] for _ in range(min(10, len(h)))] def follow(self, a, b): if a != b: self.follows[a].add(b) def unfollow(self, a, b): self.follows[a].discard(b)
A12: 11 | B12: Design Add and Search Words Data Structure | C12: Google | D12: String | E12: Medium | F12: class WordDictionary: def __init__(self): self.r = {} def addWord(self, w): n = self.r for c in w: n = n.setdefault(c, {}) n['#'] = True def search(self, w): def dfs(i, n): if i == len(w): return '#' in n c = w[i] if c == '.': return any(k != '#' and dfs(i + 1, n[k]) for k in n) return c in n and dfs(i + 1, n[c]) return dfs(0, self.r)
A13: 12 | B13: Implement Trie (Prefix Tree) | C13: Google | D13: Hash Table | E13: Medium | F13: class Trie: def __init__(self): self.r = {} def insert(self, w): n = self.r for c in w: n = n.setdefault(c, {}) n['#'] = True def _walk(self, w): n = self.r for c in w: if c not in n: return None n = n[c] return n def search(self, w): n = self._walk(w); return bool(n) and '#' in n def startsWith(self, p): return self._walk(p) is not None
... A176: 175 | B176: Minimum Interval to Include Each Query | C176: Qualcomm | D176: Arrays | E176: Hard | F176: import heapq def minInterval(intervals, queries): intervals.sort() sorted_q = sorted(set(queries)) res = {}; h = []; i = 0 for q in sorted_q: while i < len(intervals) and intervals[i][0] <= q: l, r = intervals[i] heapq.heappush(h, (r - l + 1, r)); i += 1 while h and h[0][1] < q: heapq.heappop(h) res[q] = h[0][0] if h else -1 return [res[q] for q in queries]
